<?xml version="1.0" ?>
<robot name="kmr_iiwa" xmlns:xacro="http://www.ros.org/wiki/xacro">

  <material name="Black">
    <color rgba="0.0 0.0 0.0 1.0"/>
  </material>
  <material name="Blue">
    <color rgba="0.0 0.0 0.8 1.0"/>
  </material>
  <material name="Green">
    <color rgba="0.0 0.8 0.0 1.0"/>
  </material>
  <material name="Grey">
    <color rgba="0.4 0.4 0.4 1.0"/>
  </material>
  <material name="Orange">
    <color rgba="1.0 0.423529411765 0.0392156862745 1.0"/>
  </material>
  <material name="Brown">
    <color rgba="0.870588235294 0.811764705882 0.764705882353 1.0"/>
  </material>
  <material name="Red">
    <color rgba="0.8 0.0 0.0 1.0"/>
  </material>
  <material name="White">
    <color rgba="1.0 1.0 1.0 1.0"/>
  </material>
  <material name="panda_white">
                <color rgba="1. 1. 1. 1."/>
            </material>

     <link name="world">
         <inertial>
          <origin rpy="0 0 0" xyz="0.0 0 0.00"/>
          <mass value="0.1"/>
          <inertia ixx="0.0" ixy="0" ixz="0" iyy="0.0" iyz="0" izz="0.0"/>
        </inertial>
     </link>

     <link name="kmr_link">
        <inertial>
            <origin rpy="0 0 0" xyz="0 0 0.35"/>
            <mass value="280"/>
            <inertia ixx="0.1" ixy="0" ixz="0" iyy="0.1" iyz="0" izz="0.1"/>
        </inertial>
        <visual>
            <geometry>
                <mesh filename="package://robots/kuka_kmr_iiwa/meshes/visual/kmr.stl" scale="0.001 0.001 0.001"/>
            </geometry>
            <material name="grey">
                <color rgba="0.721 0.721 0.721 1."/>
            </material>
        </visual>
        <collision>
            <origin xyz="0 0 0.3505" rpy="0 0 0" />
            <geometry>
                <box size="1.122 0.631 0.701"/>
            </geometry>
            <material name="grey"/>
        </collision>
    </link>

    <link name="help_link_0">
        <inertial>
          <origin rpy="0 0 0" xyz="0.0 0 0.00"/>
          <mass value="0.1"/>
          <inertia ixx="0.0" ixy="0" ixz="0" iyy="0.0" iyz="0" izz="0.0"/>
        </inertial>
    </link>
    <link name="help_link_1">
        <inertial>
          <origin rpy="0 0 0" xyz="0.0 0 0.00"/>
          <mass value="0.1"/>
          <inertia ixx="0.0" ixy="0" ixz="0" iyy="0.0" iyz="0" izz="0.0"/>
        </inertial>
    </link>

    <joint name="world_to_help_0_joint" type="prismatic">
        <origin rpy="0 0 0" xyz="0 0 0"/>
        <parent link="world"/>
        <child link="help_link_0"/>
        <axis xyz="1 0 0"/>
        <limit effort="100" lower="-3" upper="3" velocity="1"/>
        <!-- <limit effort="100" lower="-0.5" upper="1.25" velocity="1"/> -->
        <!-- <limit effort="100" lower="-1" upper="2" velocity="1"/> -->
        <safety_controller k_position="100" k_velocity="2" soft_lower_limit="-5" soft_upper_limit="2.93215314335"/>
    </joint>

    <joint name="help_0_to_help_1_joint" type="prismatic">
        <origin rpy="0 0 0" xyz="0 0 0"/>
        <parent link="help_link_0"/>
        <child link="help_link_1"/>
        <axis xyz="0 1 0"/>
        <limit effort="100" lower="-3" upper="3" velocity="1"/>
        <!-- <limit effort="100" lower="0.75" upper="2.45" velocity="1"/> -->
        <!-- <limit effort="100" lower="0" upper="2" velocity="1"/> -->
        <safety_controller k_position="100" k_velocity="2" soft_lower_limit="-5" soft_upper_limit="2.93215314335"/>
    </joint>

    <joint name="help_1_to_kmr_joint" type="revolute">
        <origin rpy="0 0 0" xyz="0 0 0"/>
        <parent link="help_link_1"/>
        <child link="kmr_link"/>
        <axis xyz="0 0 1"/>
        <limit effort="100" lower="-5" upper="5" velocity="1"/>
        <safety_controller k_position="100" k_velocity="2" soft_lower_limit="-5" soft_upper_limit="2.93215314335"/>
    </joint>




      <link name="iiwa_link_0">
    <inertial>
      <origin rpy="0 0 0" xyz="-0.1 0 0.07"/>
      <mass value="5"/>
      <inertia ixx="0.05" ixy="0" ixz="0" iyy="0.06" iyz="0" izz="0.03"/>
    </inertial>
    <visual>
      <origin rpy="0 0 0" xyz="0 0 0"/>
      <geometry>
        <mesh filename="package://robots/kuka_iiwa/meshes/visual/link_0.stl"/>
      </geometry>
      <material name="Grey"/>
    </visual>
    <collision>
      <origin rpy="0 0 0" xyz="0 0 0"/>
      <geometry>
        <mesh filename="package://robots/kuka_iiwa/meshes/collision/link_0.stl"/>
      </geometry>
      <material name="Grey"/>
    </collision>
  </link>

  <joint name="kmr_to_iiwa" type="fixed">
        <origin rpy="0 0 3.14" xyz="0.366 0.15 0.701"/>
        <parent link="kmr_link"/>
        <child link="iiwa_link_0"/>
    </joint>

  <!-- joint between link_0 and link_1 -->
  <joint name="iiwa_joint_1" type="revolute">
    <parent link="iiwa_link_0"/>
    <child link="iiwa_link_1"/>
    <origin rpy="0 0 0" xyz="0 0 0.1575"/>
    <axis xyz="0 0 1"/>
    <limit effort="300" lower="-2.96705972839" upper="2.96705972839" velocity="10"/>
    <safety_controller k_position="100" k_velocity="2" soft_lower_limit="-2.93215314335" soft_upper_limit="2.93215314335"/>
  </joint>

  <link name="iiwa_link_1">
    <inertial>
      <origin rpy="0 0 0" xyz="0 -0.03 0.12"/>
      <mass value="4"/>
      <inertia ixx="0.1" ixy="0" ixz="0" iyy="0.09" iyz="0" izz="0.02"/>
    </inertial>
    <visual>
      <origin rpy="0 0 0" xyz="0 0 0"/>
      <geometry>
        <mesh filename="package://robots/kuka_iiwa/meshes/visual/link_1.stl"/>
      </geometry>
      <material name="Orange"/>
    </visual>
    <collision>
      <origin rpy="0 0 0" xyz="0 0 0"/>
      <geometry>
        <mesh filename="package://robots/kuka_iiwa/meshes/collision/link_1.stl"/>
      </geometry>
      <material name="Orange"/>
    </collision>
  </link>

  <joint name="iiwa_joint_2" type="revolute">
    <parent link="iiwa_link_1"/>
    <child link="iiwa_link_2"/>
    <origin rpy="1.57079632679   0 3.14159265359" xyz="0 -0.0005 0.1840"/>
    <axis xyz="0 0 1"/>
    <limit effort="300" lower="-2.09439510239" upper="2.09439510239" velocity="10"/>
    <safety_controller k_position="100" k_velocity="2" soft_lower_limit="-2.05948851735" soft_upper_limit="2.05948851735"/>
  </joint>

  <link name="iiwa_link_2">
    <inertial>
      <origin rpy="0 0 0" xyz="0.0003 0.059 0.042"/>
      <mass value="4"/>
      <inertia ixx="0.05" ixy="0" ixz="0" iyy="0.018" iyz="0" izz="0.044"/>
    </inertial>
    <visual>
      <origin rpy="0 0 0" xyz="0 0 0"/>
      <geometry>
        <mesh filename="package://robots/kuka_iiwa/meshes/visual/link_2.stl"/>
      </geometry>
      <material name="Orange"/>
    </visual>
    <collision>
      <origin rpy="0 0 0" xyz="0 0 0"/>
      <geometry>
        <mesh filename="package://robots/kuka_iiwa/meshes/collision/link_2.stl"/>
      </geometry>
      <material name="Orange"/>
    </collision>
  </link>

  <joint name="iiwa_joint_3" type="revolute">
    <parent link="iiwa_link_2"/>
    <child link="iiwa_link_3"/>
    <origin rpy="1.57079632679 0 3.14159265359" xyz="0 0.184 0"/>
    <axis xyz="0 0 1"/>
    <limit effort="300" lower="-2.96705972839" upper="2.96705972839" velocity="10"/>
    <safety_controller k_position="100" k_velocity="2" soft_lower_limit="-2.05948851735" soft_upper_limit="2.05948851735"/>
  </joint>

  <link name="iiwa_link_3">
    <inertial>
      <origin rpy="0 0 0" xyz="0 0.03 0.13"/>
      <mass value="3"/>
      <inertia ixx="0.08" ixy="0" ixz="0" iyy="0.075" iyz="0" izz="0.01"/>
    </inertial>
    <visual>
      <origin rpy="0 0 0" xyz="0 0 0"/>
      <geometry>
        <mesh filename="package://robots/kuka_iiwa/meshes/visual/link_3.stl"/>
      </geometry>
      <material name="Orange"/>
    </visual>
    <collision>
      <origin rpy="0 0 0" xyz="0 0 0"/>
      <geometry>
        <mesh filename="package://robots/kuka_iiwa/meshes/collision/link_3.stl"/>
      </geometry>
      <material name="Orange"/>
    </collision>
  </link>

  <joint name="iiwa_joint_4" type="revolute">
    <parent link="iiwa_link_3"/>
    <child link="iiwa_link_4"/>
    <origin rpy="1.57079632679 0 0" xyz="0 0 0.21550"/>
    <axis xyz="0 0 1"/>
    <limit effort="300" lower="-2.09439510239" upper="2.09439510239" velocity="10"/>
    <safety_controller k_position="100" k_velocity="2" soft_lower_limit="-2.05948851735" soft_upper_limit="2.05948851735"/>
  </joint>

  <link name="iiwa_link_4">
    <inertial>
      <origin rpy="0 0 0" xyz="0 0.067 0.034"/>
      <mass value="2.7"/>
      <inertia ixx="0.03" ixy="0" ixz="0" iyy="0.01" iyz="0" izz="0.029"/>
    </inertial>
    <visual>
      <origin rpy="0 0 0" xyz="0 0 0"/>
      <geometry>
        <mesh filename="package://robots/kuka_iiwa/meshes/visual/link_4.stl"/>
      </geometry>
      <material name="Orange"/>
    </visual>
    <collision>
      <origin rpy="0 0 0" xyz="0 0 0"/>
      <geometry>
        <mesh filename="package://robots/kuka_iiwa/meshes/collision/link_4.stl"/>
      </geometry>
      <material name="Orange"/>
    </collision>
  </link>

  <joint name="iiwa_joint_5" type="revolute">
    <parent link="iiwa_link_4"/>
    <child link="iiwa_link_5"/>
    <origin rpy="-1.57079632679 3.14159265359 0" xyz="0 0.1840 0"/>
    <axis xyz="0 0 1"/>
    <limit effort="300" lower="-2.96705972839" upper="2.96705972839" velocity="10"/>
    <safety_controller k_position="100" k_velocity="2" soft_lower_limit="-2.05948851735" soft_upper_limit="2.05948851735"/>
  </joint>

  <link name="iiwa_link_5">
    <inertial>
      <origin rpy="0 0 0" xyz="0.0001 0.021 0.076"/>
      <mass value="1.7"/>
      <inertia ixx="0.02" ixy="0" ixz="0" iyy="0.018" iyz="0" izz="0.005"/>
    </inertial>
    <visual>
      <origin rpy="0 0 0" xyz="0 0 0"/>
      <geometry>
        <mesh filename="package://robots/kuka_iiwa/meshes/visual/link_5.stl"/>
      </geometry>
      <material name="Orange"/>
    </visual>
    <collision>
      <origin rpy="0 0 0" xyz="0 0 0"/>
      <geometry>
        <mesh filename="package://robots/kuka_iiwa/meshes/collision/link_5.stl"/>
      </geometry>
      <material name="Orange"/>
    </collision>
  </link>

  <joint name="iiwa_joint_6" type="revolute">
    <parent link="iiwa_link_5"/>
    <child link="iiwa_link_6"/>
    <origin rpy="1.57079632679 0 0" xyz="0 0.06070 0.21550"/>
    <axis xyz="0 0 1"/>
    <limit effort="300" lower="-2.09439510239" upper="2.09439510239" velocity="10"/>
    <safety_controller k_position="100" k_velocity="2" soft_lower_limit="-2.05948851735" soft_upper_limit="2.05948851735"/>
  </joint>

  <link name="iiwa_link_6">
    <inertial>
      <origin rpy="0 0 0" xyz="0 0.0006 0.0004"/>
      <mass value="1.8"/>
      <inertia ixx="0.005" ixy="0" ixz="0" iyy="0.0036" iyz="0" izz="0.0047"/>
    </inertial>
    <visual>
      <origin rpy="0 0 0" xyz="0 0 0"/>
      <geometry>
        <mesh filename="package://robots/kuka_iiwa/meshes/visual/link_6.stl"/>
      </geometry>
      <material name="Orange"/>
    </visual>
    <collision>
      <origin rpy="0 0 0" xyz="0 0 0"/>
      <geometry>
        <mesh filename="package://robots/kuka_iiwa/meshes/collision/link_6.stl"/>
      </geometry>
      <material name="Orange"/>
    </collision>
  </link>

  <joint name="iiwa_joint_7" type="revolute">
    <parent link="iiwa_link_6"/>
    <child link="iiwa_link_7"/>
    <origin rpy="-1.57079632679 3.14159265359 0" xyz="0 0.0805 0.060"/>
    <axis xyz="0 0 1"/>
    <limit effort="300" lower="-3.05432619099" upper="3.05432619099" velocity="10"/>
    <safety_controller k_position="100" k_velocity="2" soft_lower_limit="-2.05948851735" soft_upper_limit="2.05948851735"/>
  </joint>

  <link name="iiwa_link_7">
    <inertial>
      <origin rpy="0 0 0" xyz="0 0 0.02"/>
      <mass value="0.3"/>
      <inertia ixx="0.001" ixy="0" ixz="0" iyy="0.001" iyz="0" izz="0.001"/>
    </inertial>
    <visual>
      <origin rpy="0 0 0" xyz="0 0 0"/>
      <geometry>
        <mesh filename="package://robots/kuka_iiwa/meshes/visual/link_7_basic.stl"/>
      </geometry>
      <material name="Grey"/>
    </visual>
    <collision>
      <origin rpy="0 0 0" xyz="0 0 0"/>
      <geometry>
        <mesh filename="package://robots/kuka_iiwa/meshes/collision/link_7_basic.stl"/>
      </geometry>
      <material name="Grey"/>
    </collision>
  </link>

  <joint name="iiwa_joint_ee" type="fixed">
    <parent link="iiwa_link_7"/>
    <child link="iiwa_link_ee"/>
    <origin rpy="3.14159265359 3.14159265359 3.14159265359" xyz="0 0 0.045"/>
    <axis xyz="0 0 1"/>
  </joint>

  <link name="iiwa_link_ee">
        <inertial>
          <origin rpy="0 0 0" xyz="0.0 0 0.00"/>
          <mass value="0.1"/>
          <inertia ixx="0.0" ixy="0" ixz="0" iyy="0.0" iyz="0" izz="0.0"/>
        </inertial>
  </link>

  <joint name="panda_hand_joint" type="fixed">
        <parent link="iiwa_link_ee"/>
        <child link="panda_hand"/>
        <origin rpy="0 0 -0.785398163397" xyz="0 0 0"/>
    </joint>

    <link name="panda_hand">
        <inertial>
            <origin rpy="0 0 0" xyz="0 0 0.04"/>
            <mass value="0.81"/>
            <inertia ixx="0.1" ixy="0" ixz="0" iyy="0.1" iyz="0" izz="0.1"/>
        </inertial>
        <visual>
            <geometry>
                <mesh filename="package://robots/franka_panda/meshes/visual/hand.dae"/>
            </geometry>
            <material name="panda_white"/>
        </visual>
        <collision>
            <geometry>
                <mesh filename="package://robots/franka_panda/meshes/collision/hand.stl"/>
            </geometry>
            <material name="panda_white"/>
        </collision>
    </link>

    <link name="panda_leftfinger">
        <inertial>
            <origin rpy="0 0 0" xyz="0 0.01 0.02"/>
            <mass value="0.1"/>
            <inertia ixx="0.1" ixy="0" ixz="0" iyy="0.1" iyz="0" izz="0.1"/>
        </inertial>
        <visual>
            <geometry>
                <mesh filename="package://robots/franka_panda/meshes/visual/finger.dae"/>
            </geometry>
            <material name="panda_white"/>
        </visual>
        <collision>
            <geometry>
                <mesh filename="package://robots/franka_panda/meshes/collision/finger.stl"/>
            </geometry>
            <material name="panda_white"/>
        </collision>
    </link>

    <link name="panda_rightfinger">
        <inertial>
            <origin rpy="0 0 0" xyz="0 -0.01 0.02"/>
            <mass value="0.1"/>
            <inertia ixx="0.1" ixy="0" ixz="0" iyy="0.1" iyz="0" izz="0.1"/>
        </inertial>
        <visual>
            <origin rpy="0 0 3.14159265359" xyz="0 0 0"/>
            <geometry>
                <mesh filename="package://robots/franka_panda/meshes/visual/finger.dae"/>
            </geometry>
            <material name="panda_white"/>
        </visual>
        <collision>
            <origin rpy="0 0 3.14159265359" xyz="0 0 0"/>
            <geometry>
                <mesh filename="package://robots/franka_panda/meshes/collision/finger.stl"/>
            </geometry>
            <material name="panda_white"/>
        </collision>
    </link>

    <joint name="panda_finger_joint1" type="prismatic">
        <parent link="panda_hand"/>
        <child link="panda_leftfinger"/>
        <origin rpy="0 0 0" xyz="0 0 0.0584"/>
        <axis xyz="0 1 0"/>
        <limit effort="20" lower="0.0" upper="0.04" velocity="0.2"/>
    </joint>
    <joint name="panda_finger_joint2" type="prismatic">
        <parent link="panda_hand"/>
        <child link="panda_rightfinger"/>
        <origin rpy="0 0 0" xyz="0 0 0.0584"/>
        <axis xyz="0 -1 0"/>
        <limit effort="20" lower="0.0" upper="0.04" velocity="0.2"/>
        <mimic joint="panda_finger_joint1"/>
    </joint>


</robot>
