<?xml version="1.0" ?>
<!-- =================================================================================== -->
<!-- |    This document was autogenerated by xacro from panda_arm_hand.urdf.xacro      | -->
<!-- |    EDITING THIS FILE BY HAND IS NOT RECOMMENDED                                 | -->
<!-- =================================================================================== -->
<robot name="panda" xmlns:xacro="http://www.ros.org/wiki/xacro">

    <material name="white">
        <color rgba="1.0 1.0 1.0 1.0"/>
      </material>

    <link name="panda_link0">
        <visual>
            <geometry>
                <mesh filename="package://robots/franka_panda/meshes/visual/link0.dae"/>
            </geometry>
            <material name="white"/>
        </visual>
    </link>
    <link name="panda_link1">
        <visual>
            <geometry>
                <mesh filename="package://robots/franka_panda/meshes/visual/link1.dae"/>
            </geometry>
            <material name="white"/>
        </visual>
        <collision>
            <geometry>
                <mesh filename="package://robots/franka_panda/meshes/collision/link1.stl"/>
            </geometry>
            <material name="white"/>
        </collision>
    </link>
    <joint name="panda_joint1" type="revolute">
        <safety_controller k_position="100.0" k_velocity="40.0" soft_lower_limit="-2.8973" soft_upper_limit="2.8973"/>
        <origin rpy="0 0 0" xyz="0 0 0.333"/>
        <parent link="panda_link0"/>
        <child link="panda_link1"/>
        <axis xyz="0 0 1"/>
        <limit effort="87" lower="-2.9671" upper="2.9671" velocity="2.1750"/>
    </joint>
    <link name="panda_link2">
        <visual>
            <geometry>
                <mesh filename="package://robots/franka_panda/meshes/visual/link2.dae"/>
            </geometry>
            <material name="white"/>
        </visual>
        <collision>
            <geometry>
                <mesh filename="package://robots/franka_panda/meshes/collision/link2.stl"/>
            </geometry>
            <material name="white"/>
        </collision>
    </link>
    <joint name="panda_joint2" type="revolute">
        <safety_controller k_position="100.0" k_velocity="40.0" soft_lower_limit="-1.7628" soft_upper_limit="1.7628"/>
        <origin rpy="-1.57079632679 0 0" xyz="0 0 0"/>
        <parent link="panda_link1"/>
        <child link="panda_link2"/>
        <axis xyz="0 0 1"/>
        <limit effort="87" lower="-1.8326" upper="1.8326" velocity="2.1750"/>
    </joint>
    <link name="panda_link3">
        <visual>
            <geometry>
                <mesh filename="package://robots/franka_panda/meshes/visual/link3.dae"/>
            </geometry>
            <material name="white"/>
        </visual>
        <collision>
            <geometry>
                <mesh filename="package://robots/franka_panda/meshes/collision/link3.stl"/>
            </geometry>
            <material name="white"/>
        </collision>
    </link>
    <joint name="panda_joint3" type="revolute">
        <safety_controller k_position="100.0" k_velocity="40.0" soft_lower_limit="-2.8973" soft_upper_limit="2.8973"/>
        <origin rpy="1.57079632679 0 0" xyz="0 -0.316 0"/>
        <parent link="panda_link2"/>
        <child link="panda_link3"/>
        <axis xyz="0 0 1"/>
        <limit effort="87" lower="-2.9671" upper="2.9671" velocity="2.1750"/>
    </joint>
    <link name="panda_link4">
        <visual>
            <geometry>
                <mesh filename="package://robots/franka_panda/meshes/visual/link4.dae"/>
            </geometry>
            <material name="white"/>
        </visual>
        <collision>
            <geometry>
                <mesh filename="package://robots/franka_panda/meshes/collision/link4.stl"/>
            </geometry>
            <material name="white"/>
        </collision>
    </link>
    <joint name="panda_joint4" type="revolute">
        <safety_controller k_position="100.0" k_velocity="40.0" soft_lower_limit="-3.0718" soft_upper_limit="-0.0698"/>
        <origin rpy="1.57079632679 0 0" xyz="0.0825 0 0"/>
        <parent link="panda_link3"/>
        <child link="panda_link4"/>
        <axis xyz="0 0 1"/>
        <limit effort="87" lower="-3.1416" upper="0.0" velocity="2.1750"/>
    </joint>
    <link name="panda_link5">
        <visual>
            <geometry>
                <mesh filename="package://robots/franka_panda/meshes/visual/link5.dae"/>
            </geometry>
            <material name="white"/>
        </visual>
        <collision>
            <geometry>
                <mesh filename="package://robots/franka_panda/meshes/collision/link5.stl"/>
            </geometry>
            <material name="white"/>
        </collision>
    </link>
    <joint name="panda_joint5" type="revolute">
        <safety_controller k_position="100.0" k_velocity="40.0" soft_lower_limit="-2.8973" soft_upper_limit="2.8973"/>
        <origin rpy="-1.57079632679 0 0" xyz="-0.0825 0.384 0"/>
        <parent link="panda_link4"/>
        <child link="panda_link5"/>
        <axis xyz="0 0 1"/>
        <limit effort="12" lower="-2.9671" upper="2.9671" velocity="2.6100"/>
    </joint>
    <link name="panda_link6">
        <visual>
            <geometry>
                <mesh filename="package://robots/franka_panda/meshes/visual/link6.dae"/>
            </geometry>
            <material name="white"/>
        </visual>
        <collision>
            <geometry>
                <mesh filename="package://robots/franka_panda/meshes/collision/link6.stl"/>
            </geometry>
            <material name="white"/>
        </collision>
    </link>
    <joint name="panda_joint6" type="revolute">
        <safety_controller k_position="100.0" k_velocity="40.0" soft_lower_limit="-0.0175" soft_upper_limit="3.7525"/>
        <origin rpy="1.57079632679 0 0" xyz="0 0 0"/>
        <parent link="panda_link5"/>
        <child link="panda_link6"/>
        <axis xyz="0 0 1"/>
        <limit effort="12" lower="-0.0873" upper="3.8223" velocity="2.6100"/>
    </joint>
    <link name="panda_link7">
        <visual>
            <geometry>
                <mesh filename="package://robots/franka_panda/meshes/visual/link7.dae"/>
            </geometry>
            <material name="white"/>
        </visual>
        <collision>
            <geometry>
                <mesh filename="package://robots/franka_panda/meshes/collision/link7.stl"/>
            </geometry>
            <material name="white"/>
        </collision>
    </link>
    <joint name="panda_joint7" type="revolute">
        <safety_controller k_position="100.0" k_velocity="40.0" soft_lower_limit="-2.8973" soft_upper_limit="2.8973"/>
        <origin rpy="1.57079632679 0 0" xyz="0.088 0 0"/>
        <parent link="panda_link6"/>
        <child link="panda_link7"/>
        <axis xyz="0 0 1"/>
        <limit effort="12" lower="-2.9671" upper="2.9671" velocity="2.6100"/>
    </joint>
    <link name="panda_link8"/>
    <joint name="panda_joint8" type="fixed">
        <origin rpy="0 0 0" xyz="0 0 0.107"/>
        <parent link="panda_link7"/>
        <child link="panda_link8"/>
        <axis xyz="0 0 0"/>
    </joint>
    <joint name="panda_hand_joint" type="fixed">
        <parent link="panda_link8"/>
        <child link="panda_hand"/>
        <origin rpy="0 0 -0.785398163397" xyz="0 0 0"/>
    </joint>
    <link name="panda_hand">

        <visual>
            <geometry>
                <mesh filename="package://robots/franka_panda/meshes/visual/hand.dae"/>
            </geometry>
            <material name="white"/>
        </visual>
        <collision>
            <geometry>
                <mesh filename="package://robots/franka_panda/meshes/collision/hand.stl"/>
            </geometry>
        </collision>
        <material name="white"/>
    </link>
    
</robot>
